Workbook
Name ACTION: #REF!
Name ACTION: #REF!

Sheet Cover
B2: SYSTEM TEST REPORT DOCUMENT
A4: Project Name | B4: Ralsei Coach House System | E4: Creator | F4: Doan Ngoc Duc, Le Thu Ha, Nguyen Minh Thanh, Phan Duc Trung
A5: Project Code | B5: RCHS | E5: Issue Date | F5: <12/7/2026>
A6: Document Code | B6: =B5&"_"&"XXX"&"_"&"vx.x" -> RCHS_XXX_vx.x | E6: Version | F6: 1.0.0
A9: Record of change
A10: Effective Date | B10: Version | C10: Change Item | D10: *A,D,M | E10: Change description | F10: Reference
A11: <12/07/2026> | B11: 1.0.0 | C11: All sheets | D11: A | E11: Initial addition. | F11: <List of documents which are refered in this version.>

Sheet Test Cases
D1: TEST CASE LIST
B3: Project Name | D3: =Cover!B4 -> Ralsei Coach House System
B4: Project Code | D4: =Cover!B5 -> RCHS
B5: Test Environment Setup Description | D5: <List enviroment requires in this system 1. Backend Server: https://localhost:9090 (Spring Boot) 2. Database: SQL Server (seed data applied) 3. Redis: Start Redis container on Docker Desktop 4. Frontend Staff Portal: Vite React at http://localhost:2999 5. Frontend Customer Portal: Vite React at https://localhost:3000 6. Web Browser: Any modern browser applicable 7. Payment Gateway (Sepay): Requires an ngrok tunnel pointing to port 9090 for Webhook integration 8. Email Service: Configured via terminal session environment variables (requires Gmail SMTP & App Password) 9. Firebase Integration: Credentials and configurations managed locally via 'application-dev' profile and .env 10. Map & Routing Service (Goong API): API keys and endpoints managed locally via 'application-dev' profile >
B8: No | C8: Function Name | D8: Sheet Name | E8: Description | F8: Pre-Condition
B9: 1 | C9: Passenger Ticket Booking | D9: Passenger Ticket Booking | E9: As a customer or guest, I want to search trips from the homepage, select a trip, choose seats, enter passenger/itinerary info, and pay via SePay so that my ticket is confirmed, seats are sold, and I receive a confirmation email. | F9: 1. System is running (customer web + backend + DB + Redis + Firebase OTP + SePay + email). 2. At least one SCHEDULED trip exists with future departure, matching route, and ≥1 AVAILABLE seat. 3. Route has valid pickup/drop-off stops.
B10: 2 | C10: Cargo Order Booking | D10: Cargo Order Booking | E10: As ticket staff, trip staff, or an authenticated customer, I want cargo orders to be created, priced, paid, assigned, transported, received, cancelled/refunded, and tracked under strict route, agency, status, and capacity rules. | F10: 1. Backend, staff portal, customer portal, SQL Server, and payment integration are running. 2. Active origin/destination ticket agencies exist on an ordered route. 3. Active TICKET_STAFF and TRIP_STAFF accounts and a customer account are available. 4. A future SCHEDULED trip with assigned coach/staff and cargo capacity exists. 5. Active cargo types/prices and test payment callbacks are configured.

Sheet Test Statistics
B1: TEST STATISTICS
B3: Project Name | C3: =Cover!B4 -> Ralsei Coach House System | E3: Creator | H3: =Cover!F4 -> Doan Ngoc Duc, Le Thu Ha, Nguyen Minh Thanh, Phan Duc Trung
B4: Project Code | C4: =Cover!B5 -> RCHS | E4: Reviewer/Approver
B5: Document Code | C5: =C4&"_"&"Test Report"&"_"&"vx.x" -> RCHS_Test Report_vx.x | E5: Issue Date | H5: =Cover!F5 -> <12/7/2026>
B6: Notes | C6: <List modules included in this release> ex: Release 1 includes 2 modules: Module1 and Module2
B10: No | C10: Module code | D10: Passed | E10: Failed | F10: Pending | G10: N/A | H10: Number of test cases
B11: 1 | C11: Passenger Ticket Booking | D11: ='Passenger Ticket Booking'!B6 -> 23 | E11: ='Passenger Ticket Booking'!C6 -> 0 | F11: ='Passenger Ticket Booking'!D6 -> 0 | G11: ='Passenger Ticket Booking'!E6 -> 0 | H11: ='Passenger Ticket Booking'!B4 -> 31
B12: 2 | C12: Cargo Order Booking | D12: ='Cargo Order Booking'!B6 -> 32 | E12: ='Cargo Order Booking'!C6 -> 0 | F12: ='Cargo Order Booking'!D6 -> 0 | G12: ='Passenger Ticket Booking'!E6 -> 0 | H12: ='Cargo Order Booking'!B4 -> 39
C27: Sub total | D27: =SUM(D9:D26) -> 55 | E27: =SUM(E9:E26) -> 0 | F27: =SUM(F9:F26) -> 0 | G27: =SUM(G9:G26) -> 0 | H27: =SUM(H9:H26) -> 70
C29: Test coverage | E29: =(D27+E27)*100/(H27-G27) -> 78.571429 | F29: %
C30: Test successful coverage | E30: =D27*100/(H27-G27) -> 78.571429 | F30: %

Sheet Passenger Ticket Booking
A2: Workflow | B2: Passenger Ticket Booking | R2: Passed
A3: Test requirement | B3: <Brief description about requirements which are tested in this sheet> | R3: Failed
A4: Number of TCs | B4: =COUNTA(A11:A907) -> 31 | R4: Pending
A5: Testing Round | B5: Passed | C5: Failed | D5: Pending | E5: N/A | R5: N/A
A6: Round 1 | B6: =COUNTIF($F10:$F975,B5) -> 23 | C6: =COUNTIF($F10:$F975,C5) -> 0 | D6: =COUNTIF($F10:$F975,D5) -> 0 | E6: =COUNTIF($F10:$F975,E5) -> 0
A7: Round 2 | B7: =COUNTIF($I10:$I975,B5) -> 23 | C7: =COUNTIF($I10:$I975,C5) -> 0 | D7: =COUNTIF($I10:$I975,D5) -> 0 | E7: =COUNTIF($F10:$F975,E5) -> 0
A8: Round 3 | B8: =COUNTIF($L10:$L975,B5) -> 0 | C8: =COUNTIF($L10:$L975,C5) -> 0 | D8: =COUNTIF($L10:$L975,D5) -> 23 | E8: =COUNTIF($F10:$F975,E5) -> 0
A10: Test Case ID | B10: Test Case Description | C10: Test Case Procedure | D10: Expected Results | E10: Pre-conditions | F10: Round 1 | G10: Test date | H10: Tester | I10: Round 2 | J10: Test date | K10: Tester | L10: Round 3 | M10: Test date | N10: Tester | O10: Note
A11: Scenario A: Search trip on Homepage
A12: BK-TC-A01 | B12: Search one-way trips successfully | C12: 1. Open homepage. 2. Select Điểm đi, Điểm đến, Ngày đi (today or future). 3. Click Tìm lịch trình. | D12: Results list is shown for the selected route/date. Trip cards show time, vehicle, remaining seats, price. Trips with seats have Chọn chuyến enabled. | E12: Valid route/date with ≥1 bookable SCHEDULED trip. | F12: Passed | G12: 46215 | H12: Đức | I12: Passed | J12: 46222 | K12: Hà | L12: Pending
A13: BK-TC-A02 | B13: Search with no matching trips | C13: 1. Search a route/date with no future SCHEDULED trips (or no seats). | D13: Empty/no-result state is shown (or no enabled Chọn chuyến). User stays on homepage results area. | E13: No matching bookable trip for that search. | F13: Passed | G13: 46215 | H13: Đức | I13: Passed | J13: 46222 | K13: Hà | L13: Pending
A14: BK-TC-A03 | B14: Reject past departure date | C14: 1. Choose a past date. 2. Click Tìm lịch trình. | D14: System blocks from searching from a past date. | E14: N/A | F14: Passed | G14: 46215 | H14: Đức | I14: Passed | J14: 46222 | K14: Hà | L14: Pending
A15: BK-TC-A04 | B15: View pickup/drop-off stops of a trip | C15: 1. Perform A01 search. 2. On a trip card, click Xem điểm đón trả. | D15: Stop timeline modal opens with the trip’s boarding points. | E15: Trip has route stops configured. | F15: Passed | G15: 46215 | H15: Đức | I15: Passed | J15: 46222 | K15: Hà | L15: Pending
A16: Scenario B: Select trip and enter booking
A17: BK-TC-B01 | B17: Select trip and open seat selection | C17: 1. Complete A01. 2. Click Chọn chuyến on a trip with remaining seats. | D17: Navigate to Booking page. Step 1 of "Chọn ghế ngồi" is active. Trip summary (route/date) is shown. | E17: Trip has availableSeats > 0. | F17: Passed | G17: 46215 | H17: Đức | I17: Passed | J17: 46222 | K17: Hà | L17: Pending
A18: BK-TC-B02 | B18: Cannot open booking without selecting from search | C18: 1. Open /booking/trip/{tripId} directly without search navigation state. | D18: User is redirected to homepage /. Booking wizard does not start. | E18: Known valid tripId. | F18: Passed | G18: 46215 | H18: Đức | I18: Passed | J18: 46222 | K18: Hà | L18: Pending
A19: Scenario C: Select seats (Step 1)
A20: BK-TC-C01 | B20: Select and lock seats successfully | C20: 1. From B01, select 1–2 AVAILABLE seats. 2. Click Tiếp tục. | D20: Move to Step 2 Thông tin lịch trình. Selected seats are held for the session (other users see them locked). | E20: Seats are AVAILABLE. | F20: Passed | G20: 46215 | H20: Đức | I20: Passed | J20: 46222 | K20: Hà | L20: Pending
A21: BK-TC-C02 | B21: Cannot continue without selecting a seat | C21: 1. On Step 1, do not select any seat. 2. Try Tiếp tục. | D21: Cannot proceed to Step 2; system requires seat selection. | E21: On Step 1. | F21: Passed | G21: 46215 | H21: Đức | I21: Passed | J21: 46222 | K21: Hà | L21: Pending
A22: BK-TC-C03 | B22: Seat already taken by another session | C22: 1. User A locks a seat. 2. User B selects the same seat and clicks Tiếp tục. | D22: User B gets error that seat is unavailable; seat map refreshes; B stays on Step 1 / selection cleared. | E22: Concurrent sessions; seat held/sold. | F22: Passed | G22: 46215 | H22: Đức | I22: Passed | J22: 46222 | K22: Hà | L22: Pending
A23: Scenario D: Enter passenger & itinerary info (Step 2)
A24: BK-TC-D01 | B24: Fill passenger info and stops successfully | C24: 1. From C01, fill full name, phone, email for each seat. 2. Select Điểm đón and Điểm trả. 3. Check terms checkbox. 4. Do not click pay yet. | D24: Price summary updates for selected itinerary. Form is ready for payment (no blocking error). | E24: Valid hold session; valid distinct pickup before drop-off. | F24: Passed | G24: 46215 | H24: Đức | I24: Passed | J24: 46222 | K24: Hà | L24: Pending
A25: BK-TC-D02 | B25: Cannot pay without accepting terms | C25: 1. Fill valid passenger/stop data. 2. Leave terms unchecked. 3. Click Thanh toán. | D25: Submit blocked with terms validation message. | E25: On Step 2. | F25: Passed | G25: 46215 | H25: Đức | I25: Passed | J25: 46222 | K25: Hà | L25: Pending
A26: BK-TC-D03 | B26: Logged-in customer sees profile prefilled | C26: 1. Login as CUSTOMER. 2. Book to Step 2. | D26: First passenger fields are prefilled from profile (where applicable). | E26: Customer account has profile name/phone/email. | F26: Passed | G26: 46215 | H26: Đức | I26: Passed | J26: 46222 | K26: Hà | L26: Pending
A27: Scenario E: Verify phone OTP (Step 2)
A28: BK-TC-E01 | B28: Known phone skips OTP | C28: 1. On Step 2, enter a phone already known by the system. 2. Leave the field. | D28: Phone shown as known/verified; OTP modal not required for that phone. | E28: Phone exists in account/customer/prior confirmed ticket. | F28: Passed | G28: 46215 | H28: Đức | I28: Passed | J28: 46222 | K28: Hà | L28: Pending
A29: BK-TC-E02 | B29: Unknown phone requires OTP before pay | C29: 1. Enter a brand-new phone. 2. Complete OTP successfully. 3. Click Thanh toán (with other fields valid). | D29: OTP modal appears until verified; after OTP success, confirm is allowed. | E29: Phone never used in system; Firebase OTP works. | F29: Passed | G29: 46215 | H29: Đức | I29: Passed | J29: 46222 | K29: Hà | L29: Pending
A30: BK-TC-E03 | B30: Block pay when OTP not verified | C30: 1. Enter unknown phone. 2. Close/skip OTP. 3. Click Thanh toán. | D30: System blocks with OTP-required message; no payment page created. | E30: Unknown phone; OTP not completed. | F30: Passed | G30: 46215 | H30: Đức | I30: Passed | J30: 46222 | K30: Hà | L30: Pending
A31: Scenario F: Apply voucher (logged-in customer) (Step 2)
A32: BK-TC-F01 | B32: Apply valid voucher and reduce payable amount | C32: 1. Login as CUSTOMER. 2. Reach Step 2. 3. Apply a valid unused voucher. 4. Proceed to payment. | D32: Discount appears in price breakdown. Payment page amount equals discounted total. | E32: Eligible voucher; order meets min value; customer logged in. | F32: Passed | G32: 46215 | H32: Đức | I32: Passed | J32: 46222 | K32: Hà | L32: Pending
A33: BK-TC-F02 | B33: Guest cannot apply voucher | C33: 1. Book as guest to Step 2. | D33: Voucher input is not available / login warning shown. Confirm proceeds without voucher. | E33: Guest session. | F33: Passed | G33: 46215 | H33: Đức | I33: Passed | J33: 46222 | K33: Hà | L33: Pending
A34: Scenario G: Confirm booking & open payment page
A35: BK-TC-G01 | B35: Confirm booking creates pending payment | C35: 1. Complete Step 2 with valid data (+ OTP if needed). 2. Click Thanh toán. | D35: Navigate to /booking/payment/{transactionId}. Ticket/payment are pending. Payment page shows ticket code, seats, amount, SePay QR, transfer content = transactionId, ~15-min countdown. | E35: Valid Step 2 data; seat hold still active. | F35: Passed | G35: 46215 | H35: Đức | I35: Passed | J35: 46222 | K35: Hà | L35: Pending
A36: BK-TC-G02 | B36: Re-open same trip redirects to pending payment | C36: 1. After G01, without paying, go again to book the same trip. | D36: System redirects to the existing payment page instead of starting a new seat selection. | E36: Pending payment for that trip exists in current session. | F36: Passed | G36: 46215 | H36: Đức | I36: Passed | J36: 46222 | K36: Hà | L36: Pending
A37: Scenario H: Make payment (Step 3)
A38: BK-TC-H01 | B38: Pay successfully via SePay (end-to-end) | C38: 1. From G01, scan QR to pay. 2. Wait for payment status update. | D38: Success message shown; QR hidden; auto-redirect homepage ~15s. Business state: Payment COMPLETED; Ticket CONFIRMED; details CONFIRMED with boarding QR; seats SOLD; confirmation email sent to passenger email. | E38: Pending payment; SePay webhook/test transfer available; mail configured. | F38: Passed | G38: 46215 | H38: Đức | I38: Passed | J38: 46222 | K38: Hà | L38: Pending
A39: BK-TC-H02 | B39: Payment expires when not paid in time | C39: 1. Create pending payment (G01). 2. Do not transfer money. 3. Wait until countdown ends / payment expires. | D39: Expired/failed payment message. Business state: Payment FAILED; Ticket CANCELLED; details EXPIRED; seats back to AVAILABLE. | E39: Pending payment; wait full payment window (~15 min) or use test expire path. | F39: Passed | G39: 46215 | H39: Đức | I39: Passed | J39: 46222 | K39: Hà | L39: Pending
A40: BK-TC-H03 | B40: Cancel pending payment by user | C40: 1. On payment page, click Hủy thanh toán. 2. Confirm cancel. | D40: Payment shown failed/cancelled. Business state: Payment FAILED; Ticket CANCELLED; seats AVAILABLE; user can book again. | E40: Pending payment with cancel permission (session cancel token / owner). | F40: Passed | G40: 46215 | H40: Đức | I40: Passed | J40: 46222 | K40: Hà | L40: Pending
A41: BK-TC-H04 | B41: Underpaid transfer does not confirm ticket | C41: 1. From G01, transfer amount less than required. 2. Observe status within payment window. | D41: Payment stays pending (not confirmed). Ticket remains PENDING until later expiry/cancel. | E41: Ability to send underpaid SePay webhook/transfer. | F41: Passed | G41: 46215 | H41: Đức | I41: Passed | J41: 46222 | K41: Hà | L41: Pending

Sheet Cargo Order Booking
A2: Workflow | B2: Cargo Booking | R2: Passed
A3: Test requirement | B3: <Brief description about requirements which are tested in this sheet> | R3: Failed
A4: Number of TCs | B4: =COUNTA(A11:A896) -> 39 | R4: Pending
A5: Testing Round | B5: Passed | C5: Failed | D5: Pending | E5: N/A | R5: N/A
A6: Round 1 | B6: =COUNTIF($F10:$F964,B5) -> 32 | C6: =COUNTIF($F10:$F964,C5) -> 0 | D6: =COUNTIF($F10:$F964,D5) -> 0 | E6: =COUNTIF($F10:$F964,E5) -> 0
A7: Round 2 | B7: =COUNTIF($I10:$I964,B5) -> 0 | C7: =COUNTIF($I10:$I964,C5) -> 0 | D7: =COUNTIF($I10:$I964,D5) -> 0 | E7: =COUNTIF($F10:$F964,E5) -> 0
A8: Round 3 | B8: =COUNTIF($L10:$L964,B5) -> 0 | C8: =COUNTIF($L10:$L964,C5) -> 0 | D8: =COUNTIF($L10:$L964,D5) -> 0 | E8: =COUNTIF($F10:$F964,E5) -> 0
A10: Test Case ID | B10: Test Case Description | C10: Test Case Procedure | D10: Expected Results | E10: Pre-conditions | F10: Round 1 | G10: Test date | H10: Tester | I10: Round 2 | J10: Test date | K10: Tester | L10: Round 3 | M10: Test date | N10: Tester | O10: Note
A11: Scenario A: Access and cargo workspace
A12: CG-TC-A01 | B12: Ticket staff can open Cargo Booking | C12: 1. Sign in as an active TICKET_STAFF account. 2. Open /staff/cargo-tickets. | D12: Cargo operations page opens and displays Gửi hàng and Kiểm tra hàng. No authorization error is shown. | E12: Active TICKET_STAFF account linked to an active ticket agency. | F12: Passed | G12: 46227
A13: CG-TC-A02 | B13: Reject unauthorized roles | C13: 1. Sign in as CUSTOMER, MANAGER, or TRIP_STAFF. 2. Request /api/v1/ticket-staff/cargo-tickets. | D13: Request is rejected with HTTP 403 and no cargo data is disclosed. | E13: A valid account without the TICKET_STAFF role. | F13: Passed | G13: 46227
A14: CG-TC-A03 | B14: Separate send and destination-receipt workflows | C14: 1. Open Cargo Booking. 2. Select Gửi hàng, return, then select Kiểm tra hàng. | D14: Gửi hàng opens the waiting-order/upcoming-trip workflow. Kiểm tra hàng opens the receiving-trip/history workflow. | E14: A01 completed. | F14: Passed | G14: 46227
A15: Scenario B: Route, stop, and trip options
A16: CG-TC-B01 | B16: Lock pickup to the current ticket agency | C16: 1. Open Tạo đơn mới. 2. Inspect the pickup office. 3. Attempt to change pickup through the UI or request payload. | D16: Pickup is displayed read-only and remains the authenticated staff member's active agency stop. | E16: Ticket staff is linked to an active agency and stop. | F16: Passed | G16: 46227
A17: CG-TC-B02 | B17: Show only valid downstream destination offices | C17: 1. Open Tạo đơn mới. 2. Open the Điểm trả list. | D17: Only later stops on the selected route, in another city, with an active ticket office are selectable. Pickup, same-city, intermediate non-office, and reverse stops are absent. | E17: Route contains ordered stops including office and non-office stops. | F17: Passed | G17: 46227
A18: CG-TC-B03 | B18: List eligible scheduled trips and allow deferred assignment | C18: 1. Select a valid destination. 2. Open Chuyến đi phù hợp. 3. Leave the trip unselected. | D18: Only direction-compatible trips that have not started are listed. The form remains valid with Gán chuyến sau selected. | E18: At least one future SCHEDULED trip matches the ordered stops. | F18: Passed | G18: 46227
A19: CG-TC-B04 | B19: Reject agency-less, reversed, or started-trip routing | C19: 1. Submit cargo using an agency-less stop, reversed stop order, or IN_PROGRESS trip. 2. Repeat with valid offices and a SCHEDULED trip. | D19: Invalid routing is rejected with a business error and no order is created. The valid routing request is accepted. | E19: Test data contains both invalid and valid stop/trip combinations. | F19: Passed | G19: 46227
A20: Scenario C: Create cargo order
A21: CG-TC-C01 | B21: Create receiver-paid order without a trip | C21: 1. Enter valid sender/receiver data and at least one cargo item. 2. Choose Người nhận and leave trip unassigned. 3. Save. | D21: Order is created with a unique code, status RECEIVED, tripId null, derived total, and no payment method selected until destination receipt. | E21: Active price and cargo-type data; valid agency route. | F21: Passed | G21: 46227
A22: CG-TC-C02 | B22: Create sender cash-paid order | C22: 1. Enter a valid unassigned order. 2. Choose Người gửi and Tiền mặt. 3. Save. | D22: Order is RECEIVED. A payment equal to the derived total is created and immediately COMPLETED. | E22: Valid cargo form and active ticket staff. | F22: Passed | G22: 46227
A23: CG-TC-C03 | B23: Create sender bank-transfer order for later assignment | C23: 1. Enter a valid order without selecting a trip. 2. Choose Người gửi and Chuyển khoản. 3. Save. | D23: Order is RECEIVED with tripId null. Payment is PENDING and a bank-transfer QR/transaction reference is returned; assignment remains unavailable until payment completes. | E23: SePay bank configuration is available. | F23: Passed | G23: 46227
A24: CG-TC-C04 | B24: Reject sender bank transfer when a trip is preselected | C24: 1. Select a SCHEDULED trip. 2. Choose Người gửi and Chuyển khoản. 3. Save. | D24: Creation is rejected with guidance to create without a trip, complete payment, then assign the trip. No order or capacity reservation is created. | E24: Valid SCHEDULED trip and otherwise valid form. | F24: Passed | G24: 46227
A25: CG-TC-C05 | B25: Validate required contact and cargo fields | C25: 1. Submit with each required value missing/invalid in turn: names, phones, cargo type, quantity, weight, dimensions, or volume. 2. Try an order with zero items. | D25: Save remains disabled or the API returns field errors. No partial ticket, detail, or payment is persisted. | E25: Create form is open. | F25: Passed | G25: 46227
A26: CG-TC-C06 | B26: Create an order with multiple cargo items atomically | C26: 1. Add two valid cargo rows with different types and quantities. 2. Save. 3. Open order details. | D26: One ticket and both detail rows are stored in one transaction. Each detail has a calculated price and the ticket total equals the sum of all detail prices. | E26: Two active cargo-type price records. | F26: Passed | G26: 46227
A27: CG-TC-E01 | B27: Complete sender bank payment before assignment | C27: 1. Create a sender bank-transfer order. 2. Complete the configured payment callback. 3. Refresh the waiting queue. | D27: Payment changes PENDING → COMPLETED and the order becomes eligible for trip assignment. | E27: C03 completed; payment callback/test mechanism available. | F27: Passed | G27: 46227
A28: CG-TC-E02 | B28: Block unpaid sender order from assignment and loading | C28: 1. Keep sender bank payment PENDING. 2. Query assignable cargo and attempt assignment/loading. | D28: Order is absent from the assignable board; direct assignment and load attempts are rejected. Status remains RECEIVED. | E28: Sender-paid order with PENDING payment. | F28: Passed | G28: 46227
A29: CG-TC-E03 | B29: Allow receiver-paid order to travel while unpaid | C29: 1. Create a receiver-paid order. 2. Assign it to an eligible trip. 3. Load it. | D29: Pending destination payment does not block assignment or loading. Payment is selected/collected at destination. | E29: Receiver-paid RECEIVED order and eligible trip. | F29: Passed | G29: 46227
A30: CG-TC-E04 | B30: Collect receiver cash during delivery | C30: 1. Unload a receiver-paid order at destination. 2. Select Tiền mặt. 3. Confirm receipt. | D30: A cash payment is created/completed and the cargo status changes ARRIVED → DELIVERED atomically. | E30: ARRIVED receiver-paid order at the staff member's destination office. | F30: Passed | G30: 46227
A31: CG-TC-E05 | B31: Block delivery until receiver bank transfer completes | C31: 1. For ARRIVED receiver-paid cargo, select Chuyển khoản. 2. Confirm before payment. 3. Complete transfer and confirm again. | D31: First confirmation is rejected and status stays ARRIVED. After payment becomes COMPLETED, confirmation succeeds and status becomes DELIVERED. | E31: ARRIVED receiver-paid order; payment integration available. | F31: Passed | G31: 46227
A32: Scenario E: Payment lifecycle
A33: CG-TC-E01 | B33: Complete sender bank payment before assignment | C33: 1. Create a sender bank-transfer order. 2. Complete the configured payment callback. 3. Refresh the waiting queue. | D33: Payment changes PENDING → COMPLETED and the order becomes eligible for trip assignment. | E33: C03 completed; payment callback/test mechanism available. | F33: Passed | G33: 46227
A34: CG-TC-E02 | B34: Block unpaid sender order from assignment and loading | C34: 1. Keep sender bank payment PENDING. 2. Query assignable cargo and attempt assignment/loading. | D34: Order is absent from the assignable board; direct assignment and load attempts are rejected. Status remains RECEIVED. | E34: Sender-paid order with PENDING payment. | F34: Passed | G34: 46227
A35: CG-TC-E03 | B35: Allow receiver-paid order to travel while unpaid | C35: 1. Create a receiver-paid order. 2. Assign it to an eligible trip. 3. Load it. | D35: Pending destination payment does not block assignment or loading. Payment is selected/collected at destination. | E35: Receiver-paid RECEIVED order and eligible trip. | F35: Passed | G35: 46227
A36: CG-TC-E04 | B36: Collect receiver cash during delivery | C36: 1. Unload a receiver-paid order at destination. 2. Select Tiền mặt. 3. Confirm receipt. | D36: A cash payment is created/completed and the cargo status changes ARRIVED → DELIVERED atomically. | E36: ARRIVED receiver-paid order at the staff member's destination office. | F36: Passed | G36: 46227
A37: CG-TC-E05 | B37: Block delivery until receiver bank transfer completes | C37: 1. For ARRIVED receiver-paid cargo, select Chuyển khoản. 2. Confirm before payment. 3. Complete transfer and confirm again. | D37: First confirmation is rejected and status stays ARRIVED. After payment becomes COMPLETED, confirmation succeeds and status becomes DELIVERED. | E37: ARRIVED receiver-paid order; payment integration available. | F37: Passed | G37: 46227
A38: Scenario F: Waiting queue, update, cancellation, and lookup
A39: CG-TC-F01 | B39: Filter and inspect the agency waiting queue | C39: 1. Open Gửi hàng → Đơn hàng đang chờ. 2. Filter/page the list. 3. Open one order. | D39: Only non-abandoned orders operationally owned by the current agency are shown. Details display parties, route, items, volume, payment, and responsibility data. | E39: Current agency has RECEIVED orders. | F39: Passed | G39: 46227
A40: CG-TC-F02 | B40: Update only editable unpaid RECEIVED orders | C40: 1. Edit an unpaid RECEIVED order and save valid changes. 2. Try changing fee payer, payment method, or total-driving details after payment COMPLETED. | D40: Valid unpaid update succeeds and derived totals synchronize. Paid money-field changes and updates outside RECEIVED are rejected. | E40: One unpaid and one paid cargo order. | F40: Passed | G40: 46227
A41: CG-TC-F03 | B41: Cancel pending and paid waiting orders safely | C41: 1. Cancel a RECEIVED order with PENDING payment. 2. Cancel a RECEIVED order with COMPLETED payment. | D41: Both orders become CANCELLED. Pending payment becomes FAILED. Completed payment creates a PENDING refund request instead of silently reversing money. | E41: Two editable RECEIVED orders with the specified payment states. | F41: Passed | G41: 46227
A42: CG-TC-F04 | B42: Customer views owned cargo history and route | C42: 1. Sign in as the customer linked to a cargo order. 2. Open cargo history. 3. Open details and route. | D42: Only the authenticated customer's orders are returned. Detail shows stops, parties, cargo items, price/COD/status and assigned coach/staff when available. | E42: Customer account is associated with at least one cargo order. | F42: Passed | G42: 46227
...
